[2025-07-21T16:44:09.975+0000] {taskinstance.py:1159} INFO - Dependencies all met for dep_context=non-requeueable deps ti=<TaskInstance: complex_failure_dag.sometimes_fail_task manual__2025-07-21T16:43:48.490827+00:00 [queued]>
[2025-07-21T16:44:09.983+0000] {taskinstance.py:1159} INFO - Dependencies all met for dep_context=requeueable deps ti=<TaskInstance: complex_failure_dag.sometimes_fail_task manual__2025-07-21T16:43:48.490827+00:00 [queued]>
[2025-07-21T16:44:09.983+0000] {taskinstance.py:1361} INFO - Starting attempt 1 of 3
[2025-07-21T16:44:09.996+0000] {taskinstance.py:1382} INFO - Executing <Task(PythonOperator): sometimes_fail_task> on 2025-07-21 16:43:48.490827+00:00
[2025-07-21T16:44:10.001+0000] {standard_task_runner.py:57} INFO - Started process 291 to run task
[2025-07-21T16:44:10.004+0000] {standard_task_runner.py:84} INFO - Running: ['***', 'tasks', 'run', 'complex_failure_dag', 'sometimes_fail_task', 'manual__2025-07-21T16:43:48.490827+00:00', '--job-id', '13', '--raw', '--subdir', 'DAGS_FOLDER/complex_failure_dag.py', '--cfg-path', '/tmp/tmp9xloxpqo']
[2025-07-21T16:44:10.006+0000] {standard_task_runner.py:85} INFO - Job 13: Subtask sometimes_fail_task
[2025-07-21T16:44:10.045+0000] {task_command.py:416} INFO - Running <TaskInstance: complex_failure_dag.sometimes_fail_task manual__2025-07-21T16:43:48.490827+00:00 [running]> on host 2cf9a9b2cf2c
[2025-07-21T16:44:10.105+0000] {taskinstance.py:1662} INFO - Exporting env vars: AIRFLOW_CTX_DAG_OWNER='metadata_test' AIRFLOW_CTX_DAG_ID='complex_failure_dag' AIRFLOW_CTX_TASK_ID='sometimes_fail_task' AIRFLOW_CTX_EXECUTION_DATE='2025-07-21T16:43:48.490827+00:00' AIRFLOW_CTX_TRY_NUMBER='1' AIRFLOW_CTX_DAG_RUN_ID='manual__2025-07-21T16:43:48.490827+00:00'
[2025-07-21T16:44:10.106+0000] {task_logging_plugin.py:29} INFO - Task Metadata (running): {'event': 'TASK_RUNNING', 'timestamp': '2025-07-21T16:44:10.105955', 'dag_id': 'complex_failure_dag', 'dag_run_id': 'manual__2025-07-21T16:43:48.490827+00:00', 'task_id': 'sometimes_fail_task', 'execution_date': '2025-07-21 16:43:48.490827+00:00', 'try_number': 1, 'start_date': '2025-07-21 16:44:09.976026+00:00', 'end_date': 'None', 'state': 'running', 'queue': 'default', 'operator': 'PythonOperator', 'hostname': '2cf9a9b2cf2c'}
[2025-07-21T16:44:10.106+0000] {task_logging_plugin.py:33} INFO - Task Metadata (running): {'event': 'TASK_RUNNING', 'timestamp': '2025-07-21T16:44:10.105955', 'dag_id': 'complex_failure_dag', 'dag_run_id': 'manual__2025-07-21T16:43:48.490827+00:00', 'task_id': 'sometimes_fail_task', 'execution_date': '2025-07-21 16:43:48.490827+00:00', 'try_number': 1, 'start_date': '2025-07-21 16:44:09.976026+00:00', 'end_date': 'None', 'state': 'running', 'queue': 'default', 'operator': 'PythonOperator', 'hostname': '2cf9a9b2cf2c'}
[2025-07-21T16:44:10.106+0000] {task_logging_plugin.py:29} INFO - Task Metadata (failed): {'event': 'TASK_FAILED', 'timestamp': '2025-07-21T16:44:10.106613', 'dag_id': 'complex_failure_dag', 'dag_run_id': 'manual__2025-07-21T16:43:48.490827+00:00', 'task_id': 'sometimes_fail_task', 'execution_date': '2025-07-21 16:43:48.490827+00:00', 'try_number': 1, 'start_date': '2025-07-21 16:44:09.976026+00:00', 'end_date': 'None', 'state': 'running', 'queue': 'default', 'operator': 'PythonOperator', 'hostname': '2cf9a9b2cf2c'}
[2025-07-21T16:44:10.106+0000] {task_logging_plugin.py:33} INFO - Task Metadata (failed): {'event': 'TASK_FAILED', 'timestamp': '2025-07-21T16:44:10.106613', 'dag_id': 'complex_failure_dag', 'dag_run_id': 'manual__2025-07-21T16:43:48.490827+00:00', 'task_id': 'sometimes_fail_task', 'execution_date': '2025-07-21 16:43:48.490827+00:00', 'try_number': 1, 'start_date': '2025-07-21 16:44:09.976026+00:00', 'end_date': 'None', 'state': 'running', 'queue': 'default', 'operator': 'PythonOperator', 'hostname': '2cf9a9b2cf2c'}
[2025-07-21T16:44:10.106+0000] {taskinstance.py:1937} ERROR - Task failed with exception
Traceback (most recent call last):
  File "/home/airflow/.local/lib/python3.8/site-packages/airflow/operators/python.py", line 192, in execute
    return_value = self.execute_callable()
  File "/home/airflow/.local/lib/python3.8/site-packages/airflow/operators/python.py", line 209, in execute_callable
    return self.python_callable(*self.op_args, **self.op_kwargs)
  File "/opt/airflow/dags/complex_failure_dag.py", line 34, in sometimes_fail_task
    """Task that randomly fails to demonstrate retry behavior"""[37][41][42]
IndexError: string index out of range
[2025-07-21T16:44:10.114+0000] {taskinstance.py:1400} INFO - Marking task as UP_FOR_RETRY. dag_id=complex_failure_dag, task_id=sometimes_fail_task, execution_date=20250721T164348, start_date=20250721T164409, end_date=20250721T164410
[2025-07-21T16:44:10.125+0000] {standard_task_runner.py:104} ERROR - Failed to execute job 13 for task sometimes_fail_task (string index out of range; 291)
[2025-07-21T16:44:10.136+0000] {local_task_job_runner.py:228} INFO - Task exited with return code 1
[2025-07-21T16:44:10.156+0000] {taskinstance.py:2778} INFO - 0 downstream tasks scheduled from follow-on schedule check
